Workbook

Sheet Inputs - Products
A1: Financial Model
A3: Variables
A6: PRODUCTS | B6: REVENUE | C6: Cost of Goods Sold (COGS)
A7: Product/ Service/ Revenue Stream Names | B7: Price/ Revenue per user (average selling price - ASP) | C7: Paymemt transaction fees (1.5%) | D7: Contract trainers | E7: Manufacturing costs | F7: Cloud / hosting costs (AWS/ Google Cloud) | G7: {COGS} | H7: {COGS} | I7: {COGS} | J7: {COGS} | K7: {COGS} | L7: {COGS} | M7: {COGS} | N7: {COGS} | O7: {COGS} | P7: Total COGS | Q7: Gross Profit | R7: Gross Margin
A8: Isotretinoin Monitoring App - Annual Provider Subscription | B8: 24000 | C8: 360 | D8: 1000 | E8: 0 | F8: 800 | G8: 1200 | H8: 300 | I8: 500 | J8: 500 | K8: 400 | L8: 200 | P8: =SUM(C8:O8) -> 5260 | Q8: =B8-P8 -> 18740 | R8: =IFERROR(Q8/B8,"") -> 0.78083333
A9: Product 2 | P9: =SUM(C9:O9) -> 0 | Q9: =B9-P9 -> 0 | R9: =IFERROR(Q9/B9,"")
A10: Product 3 | P10: =SUM(C10:O10) -> 0 | Q10: =B10-P10 -> 0 | R10: =IFERROR(Q10/B10,"")
A11: Product 4 | P11: =SUM(C11:O11) -> 0 | Q11: =B11-P11 -> 0 | R11: =IFERROR(Q11/B11,"")
A12: Product 5 | P12: =SUM(C12:O12) -> 0 | Q12: =B12-P12 -> 0 | R12: =IFERROR(Q12/B12,"")
A13: Product 6 | P13: =SUM(C13:O13) -> 0 | Q13: =B13-P13 -> 0 | R13: =IFERROR(Q13/B13,"")
A16: OPENING FIGURES
A17: Opening month | B17: 45658
A18: Opening cash balance | B18: 300000
A21: SCENARIOS | B21: Change
A22: Revenues | B22: 0
A23: Direct Costs (COGS) | B23: 0
A24: Indirect Costs (OpEx) | B24: 0

Sheet Inputs - Sales & Investment
A1: Budget P&L + Cashflow
B2: Product --> | L2: Launch 2 pilots | P2: Launch 'Silver' product | T2: Launching 'Gold' product'
A3: ASSUMPTIONS -->> | B3: Marketing --> | P3: Run B2B marketing campaign
B4: Investment -->
D5: ='Inputs - Products'!B17 -> 45658 | E5: =DATE(YEAR(D5),MONTH(D5)+1,DAY(D5)) -> 45689 | F5: =DATE(YEAR(E5),MONTH(E5)+1,DAY(E5)) -> 45717 | G5: =DATE(YEAR(F5),MONTH(F5)+1,DAY(F5)) -> 45748 | H5: =DATE(YEAR(G5),MONTH(G5)+1,DAY(G5)) -> 45778 | I5: =DATE(YEAR(H5),MONTH(H5)+1,DAY(H5)) -> 45809 | J5: =DATE(YEAR(I5),MONTH(I5)+1,DAY(I5)) -> 45839 | K5: =DATE(YEAR(J5),MONTH(J5)+1,DAY(J5)) -> 45870 | L5: =DATE(YEAR(K5),MONTH(K5)+1,DAY(K5)) -> 45901 | ... AM5: =DATE(YEAR(AL5),MONTH(AL5)+1,DAY(AL5)) -> 46722
A7: UNITS SOLD
A9: ='Inputs - Products'!A8 -> Isotretinoin Monitoring App - Annual Provider Subscription | D9: 0 | J9: 1 | L9: 1 | N9: 1 | P9: 1 | R9: 1 | T9: 1 | V9: 1 | X9: 1 | Z9: 1 | AB9: 1 | AC9: 2 | AD9: 1 | AE9: 2 | AF9: 1 | AG9: 1 | AH9: 1 | AI9: 2 | AJ9: 1 | AK9: 1 | AL9: 1 | AM9: 1
A10: ='Inputs - Products'!A9 -> Product 2
A11: ='Inputs - Products'!A10 -> Product 3
A12: ='Inputs - Products'!A11 -> Product 4
A13: ='Inputs - Products'!A12 -> Product 5
A14: ='Inputs - Products'!A13 -> Product 6
A15: TOTAL UNITS | D15: =SUM(D9:D14) -> 0 | E15: =SUM(E9:E14) -> 0 | F15: =SUM(F9:F14) -> 0 | G15: =SUM(G9:G14) -> 0 | H15: =SUM(H9:H14) -> 0 | I15: =SUM(I9:I14) -> 0 | J15: =SUM(J9:J14) -> 1 | K15: =SUM(K9:K14) -> 0 | ... AM15: =SUM(AM9:AM14) -> 1
A17: INCOME | B17: Unit price/ Revenue per User
A19: ='Inputs - Products'!A8 -> Isotretinoin Monitoring App - Annual Provider Subscription | B19: ='Inputs - Products'!B8 -> 24000 | D19: =D9*$B19 -> 0 | E19: =E9*$B19 -> 0 | F19: =F9*$B19 -> 0 | G19: =G9*$B19 -> 0 | H19: =H9*$B19 -> 0 | I19: =I9*$B19 -> 0 | J19: =J9*$B19 -> 24000 | K19: =K9*$B19 -> 0 | ... AM19: =AM9*$B19 -> 24000
A20: ='Inputs - Products'!A9 -> Product 2 | B20: ='Inputs - Products'!B9 -> 0 | D20: =D10*$B20 -> 0 | E20: =E10*$B20 -> 0 | F20: =F10*$B20 -> 0 | G20: =G10*$B20 -> 0 | H20: =H10*$B20 -> 0 | I20: =I10*$B20 -> 0 | J20: =J10*$B20 -> 0 | K20: =K10*$B20 -> 0 | ... AM20: =AM10*$B20 -> 0
A21: ='Inputs - Products'!A10 -> Product 3 | B21: ='Inputs - Products'!B10 -> 0 | D21: =D11*$B21 -> 0 | E21: =E11*$B21 -> 0 | F21: =F11*$B21 -> 0 | G21: =G11*$B21 -> 0 | H21: =H11*$B21 -> 0 | I21: =I11*$B21 -> 0 | J21: =J11*$B21 -> 0 | K21: =K11*$B21 -> 0 | ... AM21: =AM11*$B21 -> 0
A22: ='Inputs - Products'!A11 -> Product 4 | B22: ='Inputs - Products'!B11 -> 0 | D22: =D12*$B22 -> 0 | E22: =E12*$B22 -> 0 | F22: =F12*$B22 -> 0 | G22: =G12*$B22 -> 0 | H22: =H12*$B22 -> 0 | I22: =I12*$B22 -> 0 | J22: =J12*$B22 -> 0 | K22: =K12*$B22 -> 0 | ... AM22: =AM12*$B22 -> 0
A23: ='Inputs - Products'!A12 -> Product 5 | B23: ='Inputs - Products'!B12 -> 0 | D23: =D13*$B23 -> 0 | E23: =E13*$B23 -> 0 | F23: =F13*$B23 -> 0 | G23: =G13*$B23 -> 0 | H23: =H13*$B23 -> 0 | I23: =I13*$B23 -> 0 | J23: =J13*$B23 -> 0 | K23: =K13*$B23 -> 0 | ... AM23: =AM13*$B23 -> 0
A24: ='Inputs - Products'!A13 -> Product 6 | B24: ='Inputs - Products'!B13 -> 0 | D24: =D14*$B24 -> 0 | E24: =E14*$B24 -> 0 | F24: =F14*$B24 -> 0 | G24: =G14*$B24 -> 0 | H24: =H14*$B24 -> 0 | I24: =I14*$B24 -> 0 | J24: =J14*$B24 -> 0 | K24: =K14*$B24 -> 0 | ... AM24: =AM14*$B24 -> 0
A25: TOTAL INCOME | D25: =SUM(D19:D24) -> 0 | E25: =SUM(E19:E24) -> 0 | F25: =SUM(F19:F24) -> 0 | G25: =SUM(G19:G24) -> 0 | H25: =SUM(H19:H24) -> 0 | I25: =SUM(I19:I24) -> 0 | J25: =SUM(J19:J24) -> 24000 | K25: =SUM(K19:K24) -> 0 | ... AM25: =SUM(AM19:AM24) -> 24000
A27: INVESTMENT & GRANTS
A29: Equity | D29: 150000 | G29: 0 | P29: 100000 | AB29: 50000
A30: Loans/ Debt | D30: 0 | G30: 0 | P30: 0 | AB30: 0
A31: Grants | D31: 0 | G31: 50000 | P31: 0 | AB31: 0
A32: TOTAL INCOME | D32: =SUM(D26:D31) -> 150000 | E32: =SUM(E26:E31) -> 0 | F32: =SUM(F26:F31) -> 0 | G32: =SUM(G26:G31) -> 50000 | H32: =SUM(H26:H31) -> 0 | I32: =SUM(I26:I31) -> 0 | J32: =SUM(J26:J31) -> 0 | K32: =SUM(K26:K31) -> 0 | ... AM32: =SUM(AM26:AM31) -> 0

Sheet Inputs - Fixed Costs (OpEx)
A1: Financial Model
A3: Variables
A6: Fixed Costs
A7: General & Administrative Costs | F7: ='Inputs - Sales & Investment'!D5 -> 45658 | G7: ='Inputs - Sales & Investment'!E5 -> 45689 | H7: ='Inputs - Sales & Investment'!F5 -> 45717 | I7: ='Inputs - Sales & Investment'!G5 -> 45748 | J7: ='Inputs - Sales & Investment'!H5 -> 45778 | K7: ='Inputs - Sales & Investment'!I5 -> 45809 | L7: ='Inputs - Sales & Investment'!J5 -> 45839 | M7: ='Inputs - Sales & Investment'!K5 -> 45870 | ... AO7: ='Inputs - Sales & Investment'!AM5 -> 46722
A8: Office Rent | B8: - | C8: - | D8: - | E8: - | F8: 0 | G8: 0 | H8: 0 | I8: 0 | J8: 0 | K8: 0 | L8: 0 | M8: 0 | N8: 0 | O8: 0 | P8: 0 | Q8: 0 | R8: 0 | S8: 0 | T8: 0 | U8: 0 | V8: 0 | W8: 0 | X8: 0 | Y8: 0 | Z8: 0 | AA8: 0 | AB8: 0 | AC8: 0 | AD8: 500 | AE8: 500 | AF8: 500 | AG8: 500 | AH8: 500 | AI8: 500 | AJ8: 500 | AK8: 500 | AL8: 500 | AM8: 500 | AN8: 500 | AO8: 500
A9: Utilities | B9: - | C9: - | D9: - | E9: - | F9: 0 | G9: 0 | H9: 0 | I9: 0 | J9: 0 | K9: 0 | L9: 0 | M9: 0 | N9: 0 | O9: 0 | P9: 0 | Q9: 0 | R9: 0 | S9: 0 | T9: 0 | U9: 0 | V9: 0 | W9: 0 | X9: 0 | Y9: 0 | Z9: 0 | AA9: 0 | AB9: 0 | AC9: 0 | AD9: 100 | AE9: 100 | AF9: 100 | AG9: 100 | AH9: 100 | AI9: 100 | AJ9: 100 | AK9: 100 | AL9: 100 | AM9: 100 | AN9: 100 | AO9: 100
A10: Cleaning & Security | B10: - | C10: - | D10: - | E10: - | F10: 0 | G10: 0 | H10: 0 | I10: 0 | J10: 0 | K10: 0 | L10: 0 | M10: 0 | N10: 0 | O10: 0 | P10: 0 | Q10: 0 | R10: 0 | S10: 0 | T10: 0 | U10: 0 | V10: 0 | W10: 0 | X10: 0 | Y10: 0 | Z10: 0 | AA10: 0 | AB10: 0 | AC10: 0 | AD10: 50 | AE10: 50 | AF10: 50 | AG10: 50 | AH10: 50 | AI10: 50 | AJ10: 50 | AK10: 50 | AL10: 50 | AM10: 50 | AN10: 50 | AO10: 50
A11: Food & Catering (per employee) | B11: - | C11: - | D11: - | E11: - | F11: 0 | G11: 0 | H11: 0 | I11: 0 | J11: 0 | K11: 0 | L11: 0 | M11: 0 | N11: 0 | O11: 0 | P11: 0 | Q11: 0 | R11: 50 | S11: 50 | T11: 50 | U11: 50 | V11: 50 | W11: 50 | X11: 50 | Y11: 50 | Z11: 50 | AA11: 50 | AB11: 50 | AC11: 50 | AD11: 100 | AE11: 100 | AF11: 100 | AG11: 100 | AH11: 100 | AI11: 100 | AJ11: 100 | AK11: 100 | AL11: 100 | AM11: 100 | AN11: 100 | AO11: 100
A12: Stationary & Printing (per employee) | B12: - | C12: - | D12: - | E12: - | F12: 25 | G12: 25 | H12: 25 | I12: 25 | J12: 25 | K12: 25 | L12: 25 | M12: 25 | N12: 25 | O12: 25 | P12: 25 | Q12: 25 | R12: 35 | S12: 35 | T12: 35 | U12: 35 | V12: 35 | W12: 35 | X12: 35 | Y12: 35 | Z12: 35 | AA12: 35 | AB12: 35 | AC12: 35 | AD12: 50 | AE12: 50 | AF12: 50 | AG12: 50 | AH12: 50 | AI12: 50 | AJ12: 50 | AK12: 50 | AL12: 50 | AM12: 50 | AN12: 50 | AO12: 50
A13: Audit & Accountancy fees | B13: - | C13: - | D13: - | E13: - | F13: 250 | G13: 250 | H13: 250 | I13: 250 | J13: 250 | K13: 250 | L13: 250 | M13: 250 | N13: 250 | O13: 250 | P13: 250 | Q13: 250 | R13: 400 | S13: 400 | T13: 400 | U13: 400 | V13: 400 | W13: 400 | X13: 400 | Y13: 400 | Z13: 400 | AA13: 400 | AB13: 400 | AC13: 400 | AD13: 600 | AE13: 600 | AF13: 600 | AG13: 600 | AH13: 600 | AI13: 600 | AJ13: 600 | AK13: 600 | AL13: 600 | AM13: 600 | AN13: 600 | AO13: 600
A14: Legal | B14: - | C14: - | D14: - | E14: - | F14: 1000 | G14: 1000 | H14: 1000 | I14: 1000 | J14: 1000 | K14: 1000 | L14: 1000 | M14: 1000 | N14: 1000 | O14: 1000 | P14: 1000 | Q14: 1000 | R14: 500 | S14: 500 | T14: 500 | U14: 500 | V14: 500 | W14: 500 | X14: 500 | Y14: 500 | Z14: 500 | AA14: 500 | AB14: 500 | AC14: 500 | AD14: 700 | AE14: 700 | AF14: 700 | AG14: 700 | AH14: 700 | AI14: 700 | AJ14: 700 | AK14: 700 | AL14: 700 | AM14: 700 | AN14: 700 | AO14: 700
A15: Phone & telephony | D15: - | E15: - | F15: 50 | G15: 50 | H15: 50 | I15: 50 | J15: 50 | K15: 50 | L15: 50 | M15: 50 | N15: 50 | O15: 50 | P15: 50 | Q15: 50 | R15: 100 | S15: 100 | T15: 100 | U15: 100 | V15: 100 | W15: 100 | X15: 100 | Y15: 100 | Z15: 100 | AA15: 100 | AB15: 100 | AC15: 100 | AD15: 150 | AE15: 150 | AF15: 150 | AG15: 150 | AH15: 150 | AI15: 150 | AJ15: 150 | AK15: 150 | AL15: 150 | AM15: 150 | AN15: 150 | AO15: 150
A16: HR & Training (per employee) | B16: - | C16: - | D16: - | E16: - | F16: 0 | G16: 0 | H16: 0 | I16: 0 | J16: 0 | K16: 0 | L16: 0 | M16: 0 | N16: 0 | O16: 0 | P16: 0 | Q16: 0 | R16: 100 | S16: 100 | T16: 100 | U16: 100 | V16: 100 | W16: 100 | X16: 100 | Y16: 100 | Z16: 100 | AA16: 100 | AB16: 100 | AC16: 100 | AD16: 150 | AE16: 150 | AF16: 150 | AG16: 150 | AH16: 150 | AI16: 150 | AJ16: 150 | AK16: 150 | AL16: 150 | AM16: 150 | AN16: 150 | AO16: 150
A17: Recruitment | B17: - | C17: - | D17: - | E17: - | F17: 100 | G17: 100 | H17: 100 | I17: 100 | J17: 100 | K17: 100 | L17: 100 | M17: 100 | N17: 100 | O17: 100 | P17: 100 | Q17: 100 | R17: 250 | S17: 250 | T17: 250 | U17: 250 | V17: 250 | W17: 250 | X17: 250 | Y17: 250 | Z17: 250 | AA17: 250 | AB17: 250 | AC17: 250 | AD17: 400 | AE17: 400 | AF17: 400 | AG17: 400 | AH17: 400 | AI17: 400 | AJ17: 400 | AK17: 400 | AL17: 400 | AM17: 400 | AN17: 400 | AO17: 400
A18: Website Costs | B18: - | C18: - | D18: - | E18: - | F18: 200 | G18: 200 | H18: 200 | I18: 200 | J18: 200 | K18: 200 | L18: 200 | M18: 200 | N18: 200 | O18: 200 | P18: 200 | Q18: 200 | R18: 300 | S18: 300 | T18: 300 | U18: 300 | V18: 300 | W18: 300 | X18: 300 | Y18: 300 | Z18: 300 | AA18: 300 | AB18: 300 | AC18: 300 | AD18: 400 | AE18: 400 | AF18: 400 | AG18: 400 | AH18: 400 | AI18: 400 | AJ18: 400 | AK18: 400 | AL18: 400 | AM18: 400 | AN18: 400 | AO18: 400
A19: Employee liability insurance (per employee) | B19: - | C19: - | D19: - | E19: - | F19: 100 | G19: 100 | H19: 100 | I19: 100 | J19: 100 | K19: 100 | L19: 100 | M19: 100 | N19: 100 | O19: 100 | P19: 100 | Q19: 100 | R19: 150 | S19: 150 | T19: 150 | U19: 150 | V19: 150 | W19: 150 | X19: 150 | Y19: 150 | Z19: 150 | AA19: 150 | AB19: 150 | AC19: 150 | AD19: 200 | AE19: 200 | AF19: 200 | AG19: 200 | AH19: 200 | AI19: 200 | AJ19: 200 | AK19: 200 | AL19: 200 | AM19: 200 | AN19: 200 | AO19: 200
A20: Software and email licenses (per employee) | B20: - | C20: - | D20: - | E20: - | F20: 250 | G20: 250 | H20: 250 | I20: 250 | J20: 250 | K20: 250 | L20: 250 | M20: 250 | N20: 250 | O20: 250 | P20: 250 | Q20: 250 | R20: 500 | S20: 500 | T20: 500 | U20: 500 | V20: 500 | W20: 500 | X20: 500 | Y20: 500 | Z20: 500 | AA20: 500 | AB20: 500 | AC20: 500 | AD20: 900 | AE20: 900 | AF20: 900 | AG20: 900 | AH20: 900 | AI20: 900 | AJ20: 900 | AK20: 900 | AL20: 900 | AM20: 900 | AN20: 900 | AO20: 900
A21: Internet Infrastructure (base rate) | B21: - | C21: - | D21: - | E21: - | F21: 50 | G21: 50 | H21: 50 | I21: 50 | J21: 50 | K21: 50 | L21: 50 | M21: 50 | N21: 50 | O21: 50 | P21: 50 | Q21: 50 | R21: 100 | S21: 100 | T21: 100 | U21: 100 | V21: 100 | W21: 100 | X21: 100 | Y21: 100 | Z21: 100 | AA21: 100 | AB21: 100 | AC21: 100 | AD21: 150 | AE21: 150 | AF21: 150 | AG21: 150 | AH21: 150 | AI21: 150 | AJ21: 150 | AK21: 150 | AL21: 150 | AM21: 150 | AN21: 150 | AO21: 150
A22: Other software | B22: - | C22: - | D22: - | E22: - | F22: 200 | G22: 200 | H22: 200 | I22: 200 | J22: 200 | K22: 200 | L22: 200 | M22: 200 | N22: 200 | O22: 200 | P22: 200 | Q22: 200 | R22: 350 | S22: 350 | T22: 350 | U22: 350 | V22: 350 | W22: 350 | X22: 350 | Y22: 350 | Z22: 350 | AA22: 350 | AB22: 350 | AC22: 350 | AD22: 500 | AE22: 500 | AF22: 500 | AG22: 500 | AH22: 500 | AI22: 500 | AJ22: 500 | AK22: 500 | AL22: 500 | AM22: 500 | AN22: 500 | AO22: 500
A23: {Other cost} | B23: - | C23: - | D23: - | E23: - | F23: 1000 | G23: 1000 | H23: 1000 | I23: 1000 | J23: 1000 | K23: 1000 | L23: 1000 | M23: 1000 | N23: 1000 | O23: 1000 | P23: 1000 | Q23: 1000 | R23: 500 | S23: 500 | T23: 500 | U23: 500 | V23: 500 | W23: 500 | X23: 500 | Y23: 500 | Z23: 500 | AA23: 500 | AB23: 500 | AC23: 500 | AD23: 700 | AE23: 700 | AF23: 700 | AG23: 700 | AH23: 700 | AI23: 700 | AJ23: 700 | AK23: 700 | AL23: 700 | AM23: 700 | AN23: 700 | AO23: 700
A24: {Other cost} | B24: - | C24: - | D24: - | E24: - | F24: 833 | G24: 833 | H24: 833 | I24: 833 | J24: 833 | K24: 833 | L24: 833 | M24: 833 | N24: 833 | O24: 833 | P24: 833 | Q24: 833 | R24: 667 | S24: 667 | T24: 667 | U24: 667 | V24: 667 | W24: 667 | X24: 667 | Y24: 667 | Z24: 667 | AA24: 667 | AB24: 667 | AC24: 667 | AD24: 833 | AE24: 833 | AF24: 833 | AG24: 833 | AH24: 833 | AI24: 833 | AJ24: 833 | AK24: 833 | AL24: 833 | AM24: 833 | AN24: 833 | AO24: 833
A25: Total General & Adminstrative Costs | F25: =SUM(F8:F24) -> 4058 | G25: =SUM(G8:G24) -> 4058 | H25: =SUM(H8:H24) -> 4058 | I25: =SUM(I8:I24) -> 4058 | J25: =SUM(J8:J24) -> 4058 | K25: =SUM(K8:K24) -> 4058 | L25: =SUM(L8:L24) -> 4058 | M25: =SUM(M8:M24) -> 4058 | ... AO25: =SUM(AO8:AO24) -> 6483
A27: Staff Costs | B27: Base Salary (monthly) | C27: Employment Start date | D27: Pension (legal minimum 3%) | E27: National Insurance | F27: =F$7 -> 45658 | G27: =G$7 -> 45689 | H27: =H$7 -> 45717 | I27: =I$7 -> 45748 | J27: =J$7 -> 45778 | K27: =K$7 -> 45809 | L27: =L$7 -> 45839 | M27: =M$7 -> 45870 | ... AO27: =AO$7 -> 46722
A28: CEO | B28: 2500 | C28: 45682 | D28: 0.03 | E28: =IF(B28<=676,0,0.138) -> 0.138 | F28: =IF(AND(F$27>=$C28,$B28>0),($B28+($B28*$D28)+($B28*$E28))," ") | G28: =IF(AND(G$27>=$C28,$B28>0),($B28+($B28*$D28)+($B28*$E28))," ") -> 2920 | H28: =IF(AND(H$27>=$C28,$B28>0),($B28+($B28*$D28)+($B28*$E28))," ") -> 2920 | I28: =IF(AND(I$27>=$C28,$B28>0),($B28+($B28*$D28)+($B28*$E28))," ") -> 2920 | J28: =IF(AND(J$27>=$C28,$B28>0),($B28+($B28*$D28)+($B28*$E28))," ") -> 2920 | K28: =IF(AND(K$27>=$C28,$B28>0),($B28+($B28*$D28)+($B28*$E28))," ") -> 2920 | L28: =IF(AND(L$27>=$C28,$B28>0),($B28+($B28*$D28)+($B28*$E28))," ") -> 2920 | M28: =IF(AND(M$27>=$C28,$B28>0),($B28+($B28*$D28)+($B28*$E28))," ") -> 2920 | ... AO28: =IF(AND(AO$27>=$C28,$B28>0),($B28+($B28*$D28)+($B28*$E28))," ") -> 2920
A29: Head of Marketing | B29: 3000 | C29: 45682 | D29: 0.03 | E29: =IF(B29<=676,0,0.138) -> 0.138 | F29: =IF(AND(F$27>=$C29,$B29>0),($B29+($B29*$D29)+($B29*$E29))," ") | G29: =IF(AND(G$27>=$C29,$B29>0),($B29+($B29*$D29)+($B29*$E29))," ") -> 3504 | H29: =IF(AND(H$27>=$C29,$B29>0),($B29+($B29*$D29)+($B29*$E29))," ") -> 3504 | I29: =IF(AND(I$27>=$C29,$B29>0),($B29+($B29*$D29)+($B29*$E29))," ") -> 3504 | J29: =IF(AND(J$27>=$C29,$B29>0),($B29+($B29*$D29)+($B29*$E29))," ") -> 3504 | K29: =IF(AND(K$27>=$C29,$B29>0),($B29+($B29*$D29)+($B29*$E29))," ") -> 3504 | L29: =IF(AND(L$27>=$C29,$B29>0),($B29+($B29*$D29)+($B29*$E29))," ") -> 3504 | M29: =IF(AND(M$27>=$C29,$B29>0),($B29+($B29*$D29)+($B29*$E29))," ") -> 3504 | ... AO29: =IF(AND(AO$27>=$C29,$B29>0),($B29+($B29*$D29)+($B29*$E29))," ") -> 3504
A30: Ops manager | B30: 2200 | C30: 45682 | D30: 0.03 | E30: =IF(B30<=676,0,0.138) -> 0.138 | F30: =IF(AND(F$27>=$C30,$B30>0),($B30+($B30*$D30)+($B30*$E30))," ") | G30: =IF(AND(G$27>=$C30,$B30>0),($B30+($B30*$D30)+($B30*$E30))," ") -> 2569.6 | H30: =IF(AND(H$27>=$C30,$B30>0),($B30+($B30*$D30)+($B30*$E30))," ") -> 2569.6 | I30: =IF(AND(I$27>=$C30,$B30>0),($B30+($B30*$D30)+($B30*$E30))," ") -> 2569.6 | J30: =IF(AND(J$27>=$C30,$B30>0),($B30+($B30*$D30)+($B30*$E30))," ") -> 2569.6 | K30: =IF(AND(K$27>=$C30,$B30>0),($B30+($B30*$D30)+($B30*$E30))," ") -> 2569.6 | L30: =IF(AND(L$27>=$C30,$B30>0),($B30+($B30*$D30)+($B30*$E30))," ") -> 2569.6 | M30: =IF(AND(M$27>=$C30,$B30>0),($B30+($B30*$D30)+($B30*$E30))," ") -> 2569.6 | ... AO30: =IF(AND(AO$27>=$C30,$B30>0),($B30+($B30*$D30)+($B30*$E30))," ") -> 2569.6
A31: Software Developer | B31: 3500 | C31: 45682 | D31: 0.03 | E31: =IF(B31<=676,0,0.138) -> 0.138 | F31: =IF(AND(F$27>=$C31,$B31>0),($B31+($B31*$D31)+($B31*$E31))," ") | G31: =IF(AND(G$27>=$C31,$B31>0),($B31+($B31*$D31)+($B31*$E31))," ") -> 4088 | H31: =IF(AND(H$27>=$C31,$B31>0),($B31+($B31*$D31)+($B31*$E31))," ") -> 4088 | I31: =IF(AND(I$27>=$C31,$B31>0),($B31+($B31*$D31)+($B31*$E31))," ") -> 4088 | J31: =IF(AND(J$27>=$C31,$B31>0),($B31+($B31*$D31)+($B31*$E31))," ") -> 4088 | K31: =IF(AND(K$27>=$C31,$B31>0),($B31+($B31*$D31)+($B31*$E31))," ") -> 4088 | L31: =IF(AND(L$27>=$C31,$B31>0),($B31+($B31*$D31)+($B31*$E31))," ") -> 4088 | M31: =IF(AND(M$27>=$C31,$B31>0),($B31+($B31*$D31)+($B31*$E31))," ") -> 4088 | ... AO31: =IF(AND(AO$27>=$C31,$B31>0),($B31+($B31*$D31)+($B31*$E31))," ") -> 4088
D32: 0.03 | E32: =IF(B32<=676,0,0.138) -> 0 | F32: =IF(AND(F$27>=$C32,$B32>0),($B32+($B32*$D32)+($B32*$E32))," ") | G32: =IF(AND(G$27>=$C32,$B32>0),($B32+($B32*$D32)+($B32*$E32))," ") | H32: =IF(AND(H$27>=$C32,$B32>0),($B32+($B32*$D32)+($B32*$E32))," ") | I32: =IF(AND(I$27>=$C32,$B32>0),($B32+($B32*$D32)+($B32*$E32))," ") | J32: =IF(AND(J$27>=$C32,$B32>0),($B32+($B32*$D32)+($B32*$E32))," ") | K32: =IF(AND(K$27>=$C32,$B32>0),($B32+($B32*$D32)+($B32*$E32))," ") | L32: =IF(AND(L$27>=$C32,$B32>0),($B32+($B32*$D32)+($B32*$E32))," ") | M32: =IF(AND(M$27>=$C32,$B32>0),($B32+($B32*$D32)+($B32*$E32))," ") | ... AO32: =IF(AND(AO$27>=$C32,$B32>0),($B32+($B32*$D32)+($B32*$E32))," ")
A33: {Staff member} | D33: 0.03 | E33: =IF(B33<=676,0,0.138) -> 0 | F33: =IF(AND(F$27>=$C33,$B33>0),($B33+($B33*$D33)+($B33*$E33))," ") | G33: =IF(AND(G$27>=$C33,$B33>0),($B33+($B33*$D33)+($B33*$E33))," ") | H33: =IF(AND(H$27>=$C33,$B33>0),($B33+($B33*$D33)+($B33*$E33))," ") | I33: =IF(AND(I$27>=$C33,$B33>0),($B33+($B33*$D33)+($B33*$E33))," ") | J33: =IF(AND(J$27>=$C33,$B33>0),($B33+($B33*$D33)+($B33*$E33))," ") | K33: =IF(AND(K$27>=$C33,$B33>0),($B33+($B33*$D33)+($B33*$E33))," ") | L33: =IF(AND(L$27>=$C33,$B33>0),($B33+($B33*$D33)+($B33*$E33))," ") | M33: =IF(AND(M$27>=$C33,$B33>0),($B33+($B33*$D33)+($B33*$E33))," ") | ... AO33: =IF(AND(AO$27>=$C33,$B33>0),($B33+($B33*$D33)+($B33*$E33))," ")
A34: {Staff member} | D34: 0.03 | E34: =IF(B34<=676,0,0.138) -> 0 | F34: =IF(AND(F$27>=$C34,$B34>0),($B34+($B34*$D34)+($B34*$E34))," ") | G34: =IF(AND(G$27>=$C34,$B34>0),($B34+($B34*$D34)+($B34*$E34))," ") | H34: =IF(AND(H$27>=$C34,$B34>0),($B34+($B34*$D34)+($B34*$E34))," ") | I34: =IF(AND(I$27>=$C34,$B34>0),($B34+($B34*$D34)+($B34*$E34))," ") | J34: =IF(AND(J$27>=$C34,$B34>0),($B34+($B34*$D34)+($B34*$E34))," ") | K34: =IF(AND(K$27>=$C34,$B34>0),($B34+($B34*$D34)+($B34*$E34))," ") | L34: =IF(AND(L$27>=$C34,$B34>0),($B34+($B34*$D34)+($B34*$E34))," ") | M34: =IF(AND(M$27>=$C34,$B34>0),($B34+($B34*$D34)+($B34*$E34))," ") | ... AO34: =IF(AND(AO$27>=$C34,$B34>0),($B34+($B34*$D34)+($B34*$E34))," ")
A35: {Staff member} | D35: 0.03 | E35: =IF(B35<=676,0,0.138) -> 0 | F35: =IF(AND(F$27>=$C35,$B35>0),($B35+($B35*$D35)+($B35*$E35))," ") | G35: =IF(AND(G$27>=$C35,$B35>0),($B35+($B35*$D35)+($B35*$E35))," ") | H35: =IF(AND(H$27>=$C35,$B35>0),($B35+($B35*$D35)+($B35*$E35))," ") | I35: =IF(AND(I$27>=$C35,$B35>0),($B35+($B35*$D35)+($B35*$E35))," ") | J35: =IF(AND(J$27>=$C35,$B35>0),($B35+($B35*$D35)+($B35*$E35))," ") | K35: =IF(AND(K$27>=$C35,$B35>0),($B35+($B35*$D35)+($B35*$E35))," ") | L35: =IF(AND(L$27>=$C35,$B35>0),($B35+($B35*$D35)+($B35*$E35))," ") | M35: =IF(AND(M$27>=$C35,$B35>0),($B35+($B35*$D35)+($B35*$E35))," ") | ... AO35: =IF(AND(AO$27>=$C35,$B35>0),($B35+($B35*$D35)+($B35*$E35))," ")
A36: Contractor | D36: 0.03 | E36: =IF(B36<=676,0,0.138) -> 0
A37: {Staff member} | D37: 0.03 | E37: =IF(B37<=676,0,0.138) -> 0 | F37: =IF(AND(F$27>=$C37,$B37>0),($B37+($B37*$D37)+($B37*$E37))," ") | G37: =IF(AND(G$27>=$C37,$B37>0),($B37+($B37*$D37)+($B37*$E37))," ") | H37: =IF(AND(H$27>=$C37,$B37>0),($B37+($B37*$D37)+($B37*$E37))," ") | I37: =IF(AND(I$27>=$C37,$B37>0),($B37+($B37*$D37)+($B37*$E37))," ") | J37: =IF(AND(J$27>=$C37,$B37>0),($B37+($B37*$D37)+($B37*$E37))," ") | K37: =IF(AND(K$27>=$C37,$B37>0),($B37+($B37*$D37)+($B37*$E37))," ") | L37: =IF(AND(L$27>=$C37,$B37>0),($B37+($B37*$D37)+($B37*$E37))," ") | M37: =IF(AND(M$27>=$C37,$B37>0),($B37+($B37*$D37)+($B37*$E37))," ") | ... AO37: =IF(AND(AO$27>=$C37,$B37>0),($B37+($B37*$D37)+($B37*$E37))," ")
A38: {Staff member} | D38: 0.03 | E38: =IF(B38<=676,0,0.138) -> 0 | F38: =IF(AND(F$27>=$C38,$B38>0),($B38+($B38*$D38)+($B38*$E38))," ") | G38: =IF(AND(G$27>=$C38,$B38>0),($B38+($B38*$D38)+($B38*$E38))," ") | H38: =IF(AND(H$27>=$C38,$B38>0),($B38+($B38*$D38)+($B38*$E38))," ") | I38: =IF(AND(I$27>=$C38,$B38>0),($B38+($B38*$D38)+($B38*$E38))," ") | J38: =IF(AND(J$27>=$C38,$B38>0),($B38+($B38*$D38)+($B38*$E38))," ") | K38: =IF(AND(K$27>=$C38,$B38>0),($B38+($B38*$D38)+($B38*$E38))," ") | L38: =IF(AND(L$27>=$C38,$B38>0),($B38+($B38*$D38)+($B38*$E38))," ") | M38: =IF(AND(M$27>=$C38,$B38>0),($B38+($B38*$D38)+($B38*$E38))," ") | ... AO38: =IF(AND(AO$27>=$C38,$B38>0),($B38+($B38*$D38)+($B38*$E38))," ")
A39: {Staff member} | D39: 0.03 | E39: =IF(B39<=676,0,0.138) -> 0 | F39: =IF(AND(F$27>=$C39,$B39>0),($B39+($B39*$D39)+($B39*$E39))," ") | G39: =IF(AND(G$27>=$C39,$B39>0),($B39+($B39*$D39)+($B39*$E39))," ") | H39: =IF(AND(H$27>=$C39,$B39>0),($B39+($B39*$D39)+($B39*$E39))," ") | I39: =IF(AND(I$27>=$C39,$B39>0),($B39+($B39*$D39)+($B39*$E39))," ") | J39: =IF(AND(J$27>=$C39,$B39>0),($B39+($B39*$D39)+($B39*$E39))," ") | K39: =IF(AND(K$27>=$C39,$B39>0),($B39+($B39*$D39)+($B39*$E39))," ") | L39: =IF(AND(L$27>=$C39,$B39>0),($B39+($B39*$D39)+($B39*$E39))," ") | M39: =IF(AND(M$27>=$C39,$B39>0),($B39+($B39*$D39)+($B39*$E39))," ") | ... AO39: =IF(AND(AO$27>=$C39,$B39>0),($B39+($B39*$D39)+($B39*$E39))," ")
A40: {Staff member} | D40: 0.03 | E40: =IF(B40<=676,0,0.138) -> 0 | F40: =IF(AND(F$27>=$C40,$B40>0),($B40+($B40*$D40)+($B40*$E40))," ") | G40: =IF(AND(G$27>=$C40,$B40>0),($B40+($B40*$D40)+($B40*$E40))," ") | H40: =IF(AND(H$27>=$C40,$B40>0),($B40+($B40*$D40)+($B40*$E40))," ") | I40: =IF(AND(I$27>=$C40,$B40>0),($B40+($B40*$D40)+($B40*$E40))," ") | J40: =IF(AND(J$27>=$C40,$B40>0),($B40+($B40*$D40)+($B40*$E40))," ") | K40: =IF(AND(K$27>=$C40,$B40>0),($B40+($B40*$D40)+($B40*$E40))," ") | L40: =IF(AND(L$27>=$C40,$B40>0),($B40+($B40*$D40)+($B40*$E40))," ") | M40: =IF(AND(M$27>=$C40,$B40>0),($B40+($B40*$D40)+($B40*$E40))," ") | ... AO40: =IF(AND(AO$27>=$C40,$B40>0),($B40+($B40*$D40)+($B40*$E40))," ")
A41: {Staff member} | D41: 0.03 | E41: =IF(B41<=676,0,0.138) -> 0 | F41: =IF(AND(F$27>=$C41,$B41>0),($B41+($B41*$D41)+($B41*$E41))," ") | G41: =IF(AND(G$27>=$C41,$B41>0),($B41+($B41*$D41)+($B41*$E41))," ") | H41: =IF(AND(H$27>=$C41,$B41>0),($B41+($B41*$D41)+($B41*$E41))," ") | I41: =IF(AND(I$27>=$C41,$B41>0),($B41+($B41*$D41)+($B41*$E41))," ") | J41: =IF(AND(J$27>=$C41,$B41>0),($B41+($B41*$D41)+($B41*$E41))," ") | K41: =IF(AND(K$27>=$C41,$B41>0),($B41+($B41*$D41)+($B41*$E41))," ") | L41: =IF(AND(L$27>=$C41,$B41>0),($B41+($B41*$D41)+($B41*$E41))," ") | M41: =IF(AND(M$27>=$C41,$B41>0),($B41+($B41*$D41)+($B41*$E41))," ") | ... AO41: =IF(AND(AO$27>=$C41,$B41>0),($B41+($B41*$D41)+($B41*$E41))," ")
A42: Total Staff Expenses | F42: =SUM(F28:F41) -> 0 | G42: =SUM(G28:G41) -> 13081.6 | H42: =SUM(H28:H41) -> 13081.6 | I42: =SUM(I28:I41) -> 13081.6 | J42: =SUM(J28:J41) -> 13081.6 | K42: =SUM(K28:K41) -> 13081.6 | L42: =SUM(L28:L41) -> 13081.6 | M42: =SUM(M28:M41) -> 13081.6 | ... AO42: =SUM(AO28:AO41) -> 13081.6
A44: Marketing Expenses | F44: =F$7 -> 45658 | G44: =G$7 -> 45689 | H44: =H$7 -> 45717 | I44: =I$7 -> 45748 | J44: =J$7 -> 45778 | K44: =K$7 -> 45809 | L44: =L$7 -> 45839 | M44: =M$7 -> 45870 | ... AO44: =AO$7 -> 46722
A45: Advertising | B45: - | C45: - | D45: - | E45: - | F45: 200 | G45: 200 | H45: 200 | I45: 200 | J45: 200 | K45: 200 | L45: 200 | M45: 200 | N45: 200 | O45: 200 | P45: 200 | Q45: 200 | R45: 500 | S45: 500 | T45: 500 | U45: 500 | V45: 500 | W45: 500 | X45: 500 | Y45: 500 | Z45: 500 | AA45: 500 | AB45: 500 | AC45: 500 | AD45: 1000 | AE45: 1000 | AF45: 1000 | AG45: 1000 | AH45: 1000 | AI45: 1000 | AJ45: 1000 | AK45: 1000 | AL45: 1000 | AM45: 1000 | AN45: 1000 | AO45: 1000
...

Sheet Forecast - Cashflow
A1: Budget P&L + Cashflow
D5: ='Inputs - Fixed Costs (OpEx)'!F7 -> 45658 | E5: ='Inputs - Fixed Costs (OpEx)'!G7 -> 45689 | F5: ='Inputs - Fixed Costs (OpEx)'!H7 -> 45717 | G5: ='Inputs - Fixed Costs (OpEx)'!I7 -> 45748 | H5: ='Inputs - Fixed Costs (OpEx)'!J7 -> 45778 | I5: ='Inputs - Fixed Costs (OpEx)'!K7 -> 45809 | J5: ='Inputs - Fixed Costs (OpEx)'!L7 -> 45839 | K5: ='Inputs - Fixed Costs (OpEx)'!M7 -> 45870 | ... AM5: ='Inputs - Fixed Costs (OpEx)'!AO7 -> 46722
A7: UNITS SOLD
A9: ='Inputs - Products'!A8 -> Isotretinoin Monitoring App - Annual Provider Subscription | D9: ='Inputs - Sales & Investment'!D9 -> 0 | E9: ='Inputs - Sales & Investment'!E9 -> 0 | F9: ='Inputs - Sales & Investment'!F9 -> 0 | G9: ='Inputs - Sales & Investment'!G9 -> 0 | H9: ='Inputs - Sales & Investment'!H9 -> 0 | I9: ='Inputs - Sales & Investment'!I9 -> 0 | J9: ='Inputs - Sales & Investment'!J9 -> 1 | K9: ='Inputs - Sales & Investment'!K9 -> 0 | ... AM9: ='Inputs - Sales & Investment'!AM9 -> 1
A10: ='Inputs - Products'!A9 -> Product 2 | D10: ='Inputs - Sales & Investment'!D10 -> 0 | E10: ='Inputs - Sales & Investment'!E10 -> 0 | F10: ='Inputs - Sales & Investment'!F10 -> 0 | G10: ='Inputs - Sales & Investment'!G10 -> 0 | H10: ='Inputs - Sales & Investment'!H10 -> 0 | I10: ='Inputs - Sales & Investment'!I10 -> 0 | J10: ='Inputs - Sales & Investment'!J10 -> 0 | K10: ='Inputs - Sales & Investment'!K10 -> 0 | ... AM10: ='Inputs - Sales & Investment'!AM10 -> 0
A11: ='Inputs - Products'!A10 -> Product 3 | D11: ='Inputs - Sales & Investment'!D11 -> 0 | E11: ='Inputs - Sales & Investment'!E11 -> 0 | F11: ='Inputs - Sales & Investment'!F11 -> 0 | G11: ='Inputs - Sales & Investment'!G11 -> 0 | H11: ='Inputs - Sales & Investment'!H11 -> 0 | I11: ='Inputs - Sales & Investment'!I11 -> 0 | J11: ='Inputs - Sales & Investment'!J11 -> 0 | K11: ='Inputs - Sales & Investment'!K11 -> 0 | ... AM11: ='Inputs - Sales & Investment'!AM11 -> 0
A12: ='Inputs - Products'!A11 -> Product 4 | D12: ='Inputs - Sales & Investment'!D12 -> 0 | E12: ='Inputs - Sales & Investment'!E12 -> 0 | F12: ='Inputs - Sales & Investment'!F12 -> 0 | G12: ='Inputs - Sales & Investment'!G12 -> 0 | H12: ='Inputs - Sales & Investment'!H12 -> 0 | I12: ='Inputs - Sales & Investment'!I12 -> 0 | J12: ='Inputs - Sales & Investment'!J12 -> 0 | K12: ='Inputs - Sales & Investment'!K12 -> 0 | ... AM12: ='Inputs - Sales & Investment'!AM12 -> 0
A13: ='Inputs - Products'!A12 -> Product 5 | D13: ='Inputs - Sales & Investment'!D13 -> 0 | E13: ='Inputs - Sales & Investment'!E13 -> 0 | F13: ='Inputs - Sales & Investment'!F13 -> 0 | G13: ='Inputs - Sales & Investment'!G13 -> 0 | H13: ='Inputs - Sales & Investment'!H13 -> 0 | I13: ='Inputs - Sales & Investment'!I13 -> 0 | J13: ='Inputs - Sales & Investment'!J13 -> 0 | K13: ='Inputs - Sales & Investment'!K13 -> 0 | ... AM13: ='Inputs - Sales & Investment'!AM13 -> 0
A14: ='Inputs - Products'!A13 -> Product 6 | D14: ='Inputs - Sales & Investment'!D14 -> 0 | E14: ='Inputs - Sales & Investment'!E14 -> 0 | F14: ='Inputs - Sales & Investment'!F14 -> 0 | G14: ='Inputs - Sales & Investment'!G14 -> 0 | H14: ='Inputs - Sales & Investment'!H14 -> 0 | I14: ='Inputs - Sales & Investment'!I14 -> 0 | J14: ='Inputs - Sales & Investment'!J14 -> 0 | K14: ='Inputs - Sales & Investment'!K14 -> 0 | ... AM14: ='Inputs - Sales & Investment'!AM14 -> 0
A15: TOTAL UNITS | D15: =SUM(D9:D14) -> 0 | E15: =SUM(E9:E14) -> 0 | F15: =SUM(F9:F14) -> 0 | G15: =SUM(G9:G14) -> 0 | H15: =SUM(H9:H14) -> 0 | I15: =SUM(I9:I14) -> 0 | J15: =SUM(J9:J14) -> 1 | K15: =SUM(K9:K14) -> 0 | ... AM15: =SUM(AM9:AM14) -> 1
A17: INCOME | B17: Unit price/ Revenue per User
A19: ='Inputs - Products'!A8 -> Isotretinoin Monitoring App - Annual Provider Subscription | B19: ='Inputs - Products'!B8 -> 24000 | D19: =IF('Inputs - Products'!$B$22=0,D9*$B19,D9*$B19*(1+'Inputs - Products'!$B$22)) -> 0 | E19: =IF('Inputs - Products'!$B$22=0,E9*$B19,E9*$B19*(1+'Inputs - Products'!$B$22)) -> 0 | F19: =IF('Inputs - Products'!$B$22=0,F9*$B19,F9*$B19*(1+'Inputs - Products'!$B$22)) -> 0 | G19: =IF('Inputs - Products'!$B$22=0,G9*$B19,G9*$B19*(1+'Inputs - Products'!$B$22)) -> 0 | H19: =IF('Inputs - Products'!$B$22=0,H9*$B19,H9*$B19*(1+'Inputs - Products'!$B$22)) -> 0 | I19: =IF('Inputs - Products'!$B$22=0,I9*$B19,I9*$B19*(1+'Inputs - Products'!$B$22)) -> 0 | J19: =IF('Inputs - Products'!$B$22=0,J9*$B19,J9*$B19*(1+'Inputs - Products'!$B$22)) -> 24000 | K19: =IF('Inputs - Products'!$B$22=0,K9*$B19,K9*$B19*(1+'Inputs - Products'!$B$22)) -> 0 | ... AM19: =IF('Inputs - Products'!$B$22=0,AM9*$B19,AM9*$B19*(1+'Inputs - Products'!$B$22)) -> 24000
A20: ='Inputs - Products'!A9 -> Product 2 | B20: ='Inputs - Products'!B9 -> 0 | D20: =IF('Inputs - Products'!$B$22=0,D10*$B20,D10*$B20*(1+'Inputs - Products'!$B$22)) -> 0 | E20: =IF('Inputs - Products'!$B$22=0,E10*$B20,E10*$B20*(1+'Inputs - Products'!$B$22)) -> 0 | F20: =IF('Inputs - Products'!$B$22=0,F10*$B20,F10*$B20*(1+'Inputs - Products'!$B$22)) -> 0 | G20: =IF('Inputs - Products'!$B$22=0,G10*$B20,G10*$B20*(1+'Inputs - Products'!$B$22)) -> 0 | H20: =IF('Inputs - Products'!$B$22=0,H10*$B20,H10*$B20*(1+'Inputs - Products'!$B$22)) -> 0 | I20: =IF('Inputs - Products'!$B$22=0,I10*$B20,I10*$B20*(1+'Inputs - Products'!$B$22)) -> 0 | J20: =IF('Inputs - Products'!$B$22=0,J10*$B20,J10*$B20*(1+'Inputs - Products'!$B$22)) -> 0 | K20: =IF('Inputs - Products'!$B$22=0,K10*$B20,K10*$B20*(1+'Inputs - Products'!$B$22)) -> 0 | ... AM20: =IF('Inputs - Products'!$B$22=0,AM10*$B20,AM10*$B20*(1+'Inputs - Products'!$B$22)) -> 0
A21: ='Inputs - Products'!A10 -> Product 3 | B21: ='Inputs - Products'!B10 -> 0 | D21: =IF('Inputs - Products'!$B$22=0,D11*$B21,D11*$B21*(1+'Inputs - Products'!$B$22)) -> 0 | E21: =IF('Inputs - Products'!$B$22=0,E11*$B21,E11*$B21*(1+'Inputs - Products'!$B$22)) -> 0 | F21: =IF('Inputs - Products'!$B$22=0,F11*$B21,F11*$B21*(1+'Inputs - Products'!$B$22)) -> 0 | G21: =IF('Inputs - Products'!$B$22=0,G11*$B21,G11*$B21*(1+'Inputs - Products'!$B$22)) -> 0 | H21: =IF('Inputs - Products'!$B$22=0,H11*$B21,H11*$B21*(1+'Inputs - Products'!$B$22)) -> 0 | I21: =IF('Inputs - Products'!$B$22=0,I11*$B21,I11*$B21*(1+'Inputs - Products'!$B$22)) -> 0 | J21: =IF('Inputs - Products'!$B$22=0,J11*$B21,J11*$B21*(1+'Inputs - Products'!$B$22)) -> 0 | K21: =IF('Inputs - Products'!$B$22=0,K11*$B21,K11*$B21*(1+'Inputs - Products'!$B$22)) -> 0 | ... AM21: =IF('Inputs - Products'!$B$22=0,AM11*$B21,AM11*$B21*(1+'Inputs - Products'!$B$22)) -> 0
A22: ='Inputs - Products'!A11 -> Product 4 | B22: ='Inputs - Products'!B11 -> 0 | D22: =IF('Inputs - Products'!$B$22=0,D12*$B22,D12*$B22*(1+'Inputs - Products'!$B$22)) -> 0 | E22: =IF('Inputs - Products'!$B$22=0,E12*$B22,E12*$B22*(1+'Inputs - Products'!$B$22)) -> 0 | F22: =IF('Inputs - Products'!$B$22=0,F12*$B22,F12*$B22*(1+'Inputs - Products'!$B$22)) -> 0 | G22: =IF('Inputs - Products'!$B$22=0,G12*$B22,G12*$B22*(1+'Inputs - Products'!$B$22)) -> 0 | H22: =IF('Inputs - Products'!$B$22=0,H12*$B22,H12*$B22*(1+'Inputs - Products'!$B$22)) -> 0 | I22: =IF('Inputs - Products'!$B$22=0,I12*$B22,I12*$B22*(1+'Inputs - Products'!$B$22)) -> 0 | J22: =IF('Inputs - Products'!$B$22=0,J12*$B22,J12*$B22*(1+'Inputs - Products'!$B$22)) -> 0 | K22: =IF('Inputs - Products'!$B$22=0,K12*$B22,K12*$B22*(1+'Inputs - Products'!$B$22)) -> 0 | ... AM22: =IF('Inputs - Products'!$B$22=0,AM12*$B22,AM12*$B22*(1+'Inputs - Products'!$B$22)) -> 0
A23: ='Inputs - Products'!A12 -> Product 5 | B23: ='Inputs - Products'!B12 -> 0 | D23: =IF('Inputs - Products'!$B$22=0,D13*$B23,D13*$B23*(1+'Inputs - Products'!$B$22)) -> 0 | E23: =IF('Inputs - Products'!$B$22=0,E13*$B23,E13*$B23*(1+'Inputs - Products'!$B$22)) -> 0 | F23: =IF('Inputs - Products'!$B$22=0,F13*$B23,F13*$B23*(1+'Inputs - Products'!$B$22)) -> 0 | G23: =IF('Inputs - Products'!$B$22=0,G13*$B23,G13*$B23*(1+'Inputs - Products'!$B$22)) -> 0 | H23: =IF('Inputs - Products'!$B$22=0,H13*$B23,H13*$B23*(1+'Inputs - Products'!$B$22)) -> 0 | I23: =IF('Inputs - Products'!$B$22=0,I13*$B23,I13*$B23*(1+'Inputs - Products'!$B$22)) -> 0 | J23: =IF('Inputs - Products'!$B$22=0,J13*$B23,J13*$B23*(1+'Inputs - Products'!$B$22)) -> 0 | K23: =IF('Inputs - Products'!$B$22=0,K13*$B23,K13*$B23*(1+'Inputs - Products'!$B$22)) -> 0 | ... AM23: =IF('Inputs - Products'!$B$22=0,AM13*$B23,AM13*$B23*(1+'Inputs - Products'!$B$22)) -> 0
A24: ='Inputs - Products'!A13 -> Product 6 | B24: ='Inputs - Products'!B13 -> 0 | D24: =IF('Inputs - Products'!$B$22=0,D14*$B24,D14*$B24*(1+'Inputs - Products'!$B$22)) -> 0 | E24: =IF('Inputs - Products'!$B$22=0,E14*$B24,E14*$B24*(1+'Inputs - Products'!$B$22)) -> 0 | F24: =IF('Inputs - Products'!$B$22=0,F14*$B24,F14*$B24*(1+'Inputs - Products'!$B$22)) -> 0 | G24: =IF('Inputs - Products'!$B$22=0,G14*$B24,G14*$B24*(1+'Inputs - Products'!$B$22)) -> 0 | H24: =IF('Inputs - Products'!$B$22=0,H14*$B24,H14*$B24*(1+'Inputs - Products'!$B$22)) -> 0 | I24: =IF('Inputs - Products'!$B$22=0,I14*$B24,I14*$B24*(1+'Inputs - Products'!$B$22)) -> 0 | J24: =IF('Inputs - Products'!$B$22=0,J14*$B24,J14*$B24*(1+'Inputs - Products'!$B$22)) -> 0 | K24: =IF('Inputs - Products'!$B$22=0,K14*$B24,K14*$B24*(1+'Inputs - Products'!$B$22)) -> 0 | ... AM24: =IF('Inputs - Products'!$B$22=0,AM14*$B24,AM14*$B24*(1+'Inputs - Products'!$B$22)) -> 0
A25: TOTAL INCOME | D25: =SUM(D19:D24) -> 0 | E25: =SUM(E19:E24) -> 0 | F25: =SUM(F19:F24) -> 0 | G25: =SUM(G19:G24) -> 0 | H25: =SUM(H19:H24) -> 0 | I25: =SUM(I19:I24) -> 0 | J25: =SUM(J19:J24) -> 24000 | K25: =SUM(K19:K24) -> 0 | ... AM25: =SUM(AM19:AM24) -> 24000
A27: Less Cost of Sales | B27: COGS
A29: =A19 -> Isotretinoin Monitoring App - Annual Provider Subscription | B29: ='Inputs - Products'!P8 -> 5260 | D29: =IF(D19>0,IF('Inputs - Products'!$B$23=0,(D9*$B29),(D9*$B29*(1+'Inputs - Products'!$B$23))),0) -> 0 | E29: =IF(E19>0,IF('Inputs - Products'!$B$23=0,(E9*$B29),(E9*$B29*(1+'Inputs - Products'!$B$23))),0) -> 0 | F29: =IF(F19>0,IF('Inputs - Products'!$B$23=0,(F9*$B29),(F9*$B29*(1+'Inputs - Products'!$B$23))),0) -> 0 | G29: =IF(G19>0,IF('Inputs - Products'!$B$23=0,(G9*$B29),(G9*$B29*(1+'Inputs - Products'!$B$23))),0) -> 0 | H29: =IF(H19>0,IF('Inputs - Products'!$B$23=0,(H9*$B29),(H9*$B29*(1+'Inputs - Products'!$B$23))),0) -> 0 | I29: =IF(I19>0,IF('Inputs - Products'!$B$23=0,(I9*$B29),(I9*$B29*(1+'Inputs - Products'!$B$23))),0) -> 0 | J29: =IF(J19>0,IF('Inputs - Products'!$B$23=0,(J9*$B29),(J9*$B29*(1+'Inputs - Products'!$B$23))),0) -> 5260 | K29: =IF(K19>0,IF('Inputs - Products'!$B$23=0,(K9*$B29),(K9*$B29*(1+'Inputs - Products'!$B$23))),0) -> 0 | ... AM29: =IF(AM19>0,IF('Inputs - Products'!$B$23=0,(AM9*$B29),(AM9*$B29*(1+'Inputs - Products'!$B$23))),0) -> 5260
A30: =A20 -> Product 2 | B30: ='Inputs - Products'!P9 -> 0 | D30: =IF(D20>0,IF('Inputs - Products'!$B$23=0,(D10*$B30),(D10*$B30*(1+'Inputs - Products'!$B$23))),0) -> 0 | E30: =IF(E20>0,IF('Inputs - Products'!$B$23=0,(E10*$B30),(E10*$B30*(1+'Inputs - Products'!$B$23))),0) -> 0 | F30: =IF(F20>0,IF('Inputs - Products'!$B$23=0,(F10*$B30),(F10*$B30*(1+'Inputs - Products'!$B$23))),0) -> 0 | G30: =IF(G20>0,IF('Inputs - Products'!$B$23=0,(G10*$B30),(G10*$B30*(1+'Inputs - Products'!$B$23))),0) -> 0 | H30: =IF(H20>0,IF('Inputs - Products'!$B$23=0,(H10*$B30),(H10*$B30*(1+'Inputs - Products'!$B$23))),0) -> 0 | I30: =IF(I20>0,IF('Inputs - Products'!$B$23=0,(I10*$B30),(I10*$B30*(1+'Inputs - Products'!$B$23))),0) -> 0 | J30: =IF(J20>0,IF('Inputs - Products'!$B$23=0,(J10*$B30),(J10*$B30*(1+'Inputs - Products'!$B$23))),0) -> 0 | K30: =IF(K20>0,IF('Inputs - Products'!$B$23=0,(K10*$B30),(K10*$B30*(1+'Inputs - Products'!$B$23))),0) -> 0 | ... AM30: =IF(AM20>0,IF('Inputs - Products'!$B$23=0,(AM10*$B30),(AM10*$B30*(1+'Inputs - Products'!$B$23))),0) -> 0
A31: =A21 -> Product 3 | B31: ='Inputs - Products'!P10 -> 0 | D31: =IF(D21>0,IF('Inputs - Products'!$B$23=0,(D11*$B31),(D11*$B31*(1+'Inputs - Products'!$B$23))),0) -> 0 | E31: =IF(E21>0,IF('Inputs - Products'!$B$23=0,(E11*$B31),(E11*$B31*(1+'Inputs - Products'!$B$23))),0) -> 0 | F31: =IF(F21>0,IF('Inputs - Products'!$B$23=0,(F11*$B31),(F11*$B31*(1+'Inputs - Products'!$B$23))),0) -> 0 | G31: =IF(G21>0,IF('Inputs - Products'!$B$23=0,(G11*$B31),(G11*$B31*(1+'Inputs - Products'!$B$23))),0) -> 0 | H31: =IF(H21>0,IF('Inputs - Products'!$B$23=0,(H11*$B31),(H11*$B31*(1+'Inputs - Products'!$B$23))),0) -> 0 | I31: =IF(I21>0,IF('Inputs - Products'!$B$23=0,(I11*$B31),(I11*$B31*(1+'Inputs - Products'!$B$23))),0) -> 0 | J31: =IF(J21>0,IF('Inputs - Products'!$B$23=0,(J11*$B31),(J11*$B31*(1+'Inputs - Products'!$B$23))),0) -> 0 | K31: =IF(K21>0,IF('Inputs - Products'!$B$23=0,(K11*$B31),(K11*$B31*(1+'Inputs - Products'!$B$23))),0) -> 0 | ... AM31: =IF(AM21>0,IF('Inputs - Products'!$B$23=0,(AM11*$B31),(AM11*$B31*(1+'Inputs - Products'!$B$23))),0) -> 0
A32: =A22 -> Product 4 | B32: ='Inputs - Products'!P11 -> 0 | D32: =IF(D22>0,IF('Inputs - Products'!$B$23=0,(D12*$B32),(D12*$B32*(1+'Inputs - Products'!$B$23))),0) -> 0 | E32: =IF(E22>0,IF('Inputs - Products'!$B$23=0,(E12*$B32),(E12*$B32*(1+'Inputs - Products'!$B$23))),0) -> 0 | F32: =IF(F22>0,IF('Inputs - Products'!$B$23=0,(F12*$B32),(F12*$B32*(1+'Inputs - Products'!$B$23))),0) -> 0 | G32: =IF(G22>0,IF('Inputs - Products'!$B$23=0,(G12*$B32),(G12*$B32*(1+'Inputs - Products'!$B$23))),0) -> 0 | H32: =IF(H22>0,IF('Inputs - Products'!$B$23=0,(H12*$B32),(H12*$B32*(1+'Inputs - Products'!$B$23))),0) -> 0 | I32: =IF(I22>0,IF('Inputs - Products'!$B$23=0,(I12*$B32),(I12*$B32*(1+'Inputs - Products'!$B$23))),0) -> 0 | J32: =IF(J22>0,IF('Inputs - Products'!$B$23=0,(J12*$B32),(J12*$B32*(1+'Inputs - Products'!$B$23))),0) -> 0 | K32: =IF(K22>0,IF('Inputs - Products'!$B$23=0,(K12*$B32),(K12*$B32*(1+'Inputs - Products'!$B$23))),0) -> 0 | ... AM32: =IF(AM22>0,IF('Inputs - Products'!$B$23=0,(AM12*$B32),(AM12*$B32*(1+'Inputs - Products'!$B$23))),0) -> 0
A33: =A23 -> Product 5 | B33: ='Inputs - Products'!P12 -> 0 | D33: =IF(D23>0,IF('Inputs - Products'!$B$23=0,(D13*$B33),(D13*$B33*(1+'Inputs - Products'!$B$23))),0) -> 0 | E33: =IF(E23>0,IF('Inputs - Products'!$B$23=0,(E13*$B33),(E13*$B33*(1+'Inputs - Products'!$B$23))),0) -> 0 | F33: =IF(F23>0,IF('Inputs - Products'!$B$23=0,(F13*$B33),(F13*$B33*(1+'Inputs - Products'!$B$23))),0) -> 0 | G33: =IF(G23>0,IF('Inputs - Products'!$B$23=0,(G13*$B33),(G13*$B33*(1+'Inputs - Products'!$B$23))),0) -> 0 | H33: =IF(H23>0,IF('Inputs - Products'!$B$23=0,(H13*$B33),(H13*$B33*(1+'Inputs - Products'!$B$23))),0) -> 0 | I33: =IF(I23>0,IF('Inputs - Products'!$B$23=0,(I13*$B33),(I13*$B33*(1+'Inputs - Products'!$B$23))),0) -> 0 | J33: =IF(J23>0,IF('Inputs - Products'!$B$23=0,(J13*$B33),(J13*$B33*(1+'Inputs - Products'!$B$23))),0) -> 0 | K33: =IF(K23>0,IF('Inputs - Products'!$B$23=0,(K13*$B33),(K13*$B33*(1+'Inputs - Products'!$B$23))),0) -> 0 | ... AM33: =IF(AM23>0,IF('Inputs - Products'!$B$23=0,(AM13*$B33),(AM13*$B33*(1+'Inputs - Products'!$B$23))),0) -> 0
A34: =A24 -> Product 6 | B34: ='Inputs - Products'!P13 -> 0 | D34: =IF(D24>0,IF('Inputs - Products'!$B$23=0,(D14*$B34),(D14*$B34*(1+'Inputs - Products'!$B$23))),0) -> 0 | E34: =IF(E24>0,IF('Inputs - Products'!$B$23=0,(E14*$B34),(E14*$B34*(1+'Inputs - Products'!$B$23))),0) -> 0 | F34: =IF(F24>0,IF('Inputs - Products'!$B$23=0,(F14*$B34),(F14*$B34*(1+'Inputs - Products'!$B$23))),0) -> 0 | G34: =IF(G24>0,IF('Inputs - Products'!$B$23=0,(G14*$B34),(G14*$B34*(1+'Inputs - Products'!$B$23))),0) -> 0 | H34: =IF(H24>0,IF('Inputs - Products'!$B$23=0,(H14*$B34),(H14*$B34*(1+'Inputs - Products'!$B$23))),0) -> 0 | I34: =IF(I24>0,IF('Inputs - Products'!$B$23=0,(I14*$B34),(I14*$B34*(1+'Inputs - Products'!$B$23))),0) -> 0 | J34: =IF(J24>0,IF('Inputs - Products'!$B$23=0,(J14*$B34),(J14*$B34*(1+'Inputs - Products'!$B$23))),0) -> 0 | K34: =IF(K24>0,IF('Inputs - Products'!$B$23=0,(K14*$B34),(K14*$B34*(1+'Inputs - Products'!$B$23))),0) -> 0 | ... AM34: =IF(AM24>0,IF('Inputs - Products'!$B$23=0,(AM14*$B34),(AM14*$B34*(1+'Inputs - Products'!$B$23))),0) -> 0
A35: TOTAL COST OF SALES | D35: =SUM(D29:D34) -> 0 | E35: =SUM(E29:E34) -> 0 | F35: =SUM(F29:F34) -> 0 | G35: =SUM(G29:G34) -> 0 | H35: =SUM(H29:H34) -> 0 | I35: =SUM(I29:I34) -> 0 | J35: =SUM(J29:J34) -> 5260 | K35: =SUM(K29:K34) -> 0 | ... AM35: =SUM(AM29:AM34) -> 5260
A37: GROSS PROFIT | D37: =D25-D35 -> 0 | E37: =E25-E35 -> 0 | F37: =F25-F35 -> 0 | G37: =G25-G35 -> 0 | H37: =H25-H35 -> 0 | I37: =I25-I35 -> 0 | J37: =J25-J35 -> 18740 | K37: =K25-K35 -> 0 | ... AM37: =AM25-AM35 -> 18740
A38: Gross Margin % | D38: =IFERROR(D37/D25,0) -> 0 | E38: =IFERROR(E37/E25,0) -> 0 | F38: =IFERROR(F37/F25,0) -> 0 | G38: =IFERROR(G37/G25,0) -> 0 | H38: =IFERROR(H37/H25,0) -> 0 | I38: =IFERROR(I37/I25,0) -> 0 | J38: =IFERROR(J37/J25,0) -> 0.78083333 | K38: =IFERROR(K37/K25,0) -> 0 | ... AM38: =IFERROR(AM37/AM25,0) -> 0.78083333
A40: Operating Expenses
A41: ='Inputs - Fixed Costs (OpEx)'!A7 -> General & Administrative Costs | D41: =IF('Inputs - Products'!$B$24=0,'Inputs - Fixed Costs (OpEx)'!F25,'Inputs - Fixed Costs (OpEx)'!F25*(1+'Inputs - Products'!$B$24)) -> 4058 | E41: =IF('Inputs - Products'!$B$24=0,'Inputs - Fixed Costs (OpEx)'!G25,'Inputs - Fixed Costs (OpEx)'!G25*(1+'Inputs - Products'!$B$24)) -> 4058 | F41: =IF('Inputs - Products'!$B$24=0,'Inputs - Fixed Costs (OpEx)'!H25,'Inputs - Fixed Costs (OpEx)'!H25*(1+'Inputs - Products'!$B$24)) -> 4058 | G41: =IF('Inputs - Products'!$B$24=0,'Inputs - Fixed Costs (OpEx)'!I25,'Inputs - Fixed Costs (OpEx)'!I25*(1+'Inputs - Products'!$B$24)) -> 4058 | H41: =IF('Inputs - Products'!$B$24=0,'Inputs - Fixed Costs (OpEx)'!J25,'Inputs - Fixed Costs (OpEx)'!J25*(1+'Inputs - Products'!$B$24)) -> 4058 | I41: =IF('Inputs - Products'!$B$24=0,'Inputs - Fixed Costs (OpEx)'!K25,'Inputs - Fixed Costs (OpEx)'!K25*(1+'Inputs - Products'!$B$24)) -> 4058 | J41: =IF('Inputs - Products'!$B$24=0,'Inputs - Fixed Costs (OpEx)'!L25,'Inputs - Fixed Costs (OpEx)'!L25*(1+'Inputs - Products'!$B$24)) -> 4058 | K41: =IF('Inputs - Products'!$B$24=0,'Inputs - Fixed Costs (OpEx)'!M25,'Inputs - Fixed Costs (OpEx)'!M25*(1+'Inputs - Products'!$B$24)) -> 4058 | ... AM41: =IF('Inputs - Products'!$B$24=0,'Inputs - Fixed Costs (OpEx)'!AO25,'Inputs - Fixed Costs (OpEx)'!AO25*(1+'Inputs - Products'!$B$24)) -> 6483
A42: ='Inputs - Fixed Costs (OpEx)'!A27 -> Staff Costs | D42: =IF('Inputs - Products'!$B$24=0,'Inputs - Fixed Costs (OpEx)'!F42,'Inputs - Fixed Costs (OpEx)'!F42*(1+'Inputs - Products'!$B$24)) -> 0 | E42: =IF('Inputs - Products'!$B$24=0,'Inputs - Fixed Costs (OpEx)'!G42,'Inputs - Fixed Costs (OpEx)'!G42*(1+'Inputs - Products'!$B$24)) -> 13081.6 | F42: =IF('Inputs - Products'!$B$24=0,'Inputs - Fixed Costs (OpEx)'!H42,'Inputs - Fixed Costs (OpEx)'!H42*(1+'Inputs - Products'!$B$24)) -> 13081.6 | G42: =IF('Inputs - Products'!$B$24=0,'Inputs - Fixed Costs (OpEx)'!I42,'Inputs - Fixed Costs (OpEx)'!I42*(1+'Inputs - Products'!$B$24)) -> 13081.6 | H42: =IF('Inputs - Products'!$B$24=0,'Inputs - Fixed Costs (OpEx)'!J42,'Inputs - Fixed Costs (OpEx)'!J42*(1+'Inputs - Products'!$B$24)) -> 13081.6 | I42: =IF('Inputs - Products'!$B$24=0,'Inputs - Fixed Costs (OpEx)'!K42,'Inputs - Fixed Costs (OpEx)'!K42*(1+'Inputs - Products'!$B$24)) -> 13081.6 | J42: =IF('Inputs - Products'!$B$24=0,'Inputs - Fixed Costs (OpEx)'!L42,'Inputs - Fixed Costs (OpEx)'!L42*(1+'Inputs - Products'!$B$24)) -> 13081.6 | K42: =IF('Inputs - Products'!$B$24=0,'Inputs - Fixed Costs (OpEx)'!M42,'Inputs - Fixed Costs (OpEx)'!M42*(1+'Inputs - Products'!$B$24)) -> 13081.6 | ... AM42: =IF('Inputs - Products'!$B$24=0,'Inputs - Fixed Costs (OpEx)'!AO42,'Inputs - Fixed Costs (OpEx)'!AO42*(1+'Inputs - Products'!$B$24)) -> 13081.6
A43: ='Inputs - Fixed Costs (OpEx)'!A44 -> Marketing Expenses | D43: =IF('Inputs - Products'!$B$24=0,'Inputs - Fixed Costs (OpEx)'!F57,'Inputs - Fixed Costs (OpEx)'!F57*(1+'Inputs - Products'!$B$24)) -> 2350 | E43: =IF('Inputs - Products'!$B$24=0,'Inputs - Fixed Costs (OpEx)'!G57,'Inputs - Fixed Costs (OpEx)'!G57*(1+'Inputs - Products'!$B$24)) -> 2350 | F43: =IF('Inputs - Products'!$B$24=0,'Inputs - Fixed Costs (OpEx)'!H57,'Inputs - Fixed Costs (OpEx)'!H57*(1+'Inputs - Products'!$B$24)) -> 2350 | G43: =IF('Inputs - Products'!$B$24=0,'Inputs - Fixed Costs (OpEx)'!I57,'Inputs - Fixed Costs (OpEx)'!I57*(1+'Inputs - Products'!$B$24)) -> 2350 | H43: =IF('Inputs - Products'!$B$24=0,'Inputs - Fixed Costs (OpEx)'!J57,'Inputs - Fixed Costs (OpEx)'!J57*(1+'Inputs - Products'!$B$24)) -> 2350 | I43: =IF('Inputs - Products'!$B$24=0,'Inputs - Fixed Costs (OpEx)'!K57,'Inputs - Fixed Costs (OpEx)'!K57*(1+'Inputs - Products'!$B$24)) -> 2350 | J43: =IF('Inputs - Products'!$B$24=0,'Inputs - Fixed Costs (OpEx)'!L57,'Inputs - Fixed Costs (OpEx)'!L57*(1+'Inputs - Products'!$B$24)) -> 2350 | K43: =IF('Inputs - Products'!$B$24=0,'Inputs - Fixed Costs (OpEx)'!M57,'Inputs - Fixed Costs (OpEx)'!M57*(1+'Inputs - Products'!$B$24)) -> 2350 | ... AM43: =IF('Inputs - Products'!$B$24=0,'Inputs - Fixed Costs (OpEx)'!AO57,'Inputs - Fixed Costs (OpEx)'!AO57*(1+'Inputs - Products'!$B$24)) -> 9000
A44: ='Inputs - Fixed Costs (OpEx)'!A59 -> Other Central Expenses | D44: =IF('Inputs - Products'!$B$24=0,'Inputs - Fixed Costs (OpEx)'!F66,'Inputs - Fixed Costs (OpEx)'!F66*(1+'Inputs - Products'!$B$24)) -> 5100 | E44: ='Inputs - Fixed Costs (OpEx)'!G66 -> 5100 | F44: ='Inputs - Fixed Costs (OpEx)'!H66 -> 5100 | G44: ='Inputs - Fixed Costs (OpEx)'!I66 -> 5100 | H44: ='Inputs - Fixed Costs (OpEx)'!J66 -> 5100 | I44: ='Inputs - Fixed Costs (OpEx)'!K66 -> 5100 | J44: ='Inputs - Fixed Costs (OpEx)'!L66 -> 5100 | K44: ='Inputs - Fixed Costs (OpEx)'!M66 -> 5100 | L44: ='Inputs - Fixed Costs (OpEx)'!N66 -> 5100 | ... AM44: ='Inputs - Fixed Costs (OpEx)'!AO66 -> 6500
A45: TOTAL OPERATING EXPENSES | D45: =D41+D42+D43+D44 -> 11508 | E45: =E41+E42+E43+E44 -> 24589.6 | F45: =F41+F42+F43+F44 -> 24589.6 | G45: =G41+G42+G43+G44 -> 24589.6 | H45: =H41+H42+H43+H44 -> 24589.6 | I45: =I41+I42+I43+I44 -> 24589.6 | J45: =J41+J42+J43+J44 -> 24589.6 | K45: =K41+K42+K43+K44 -> 24589.6 | ... AM45: =AM41+AM42+AM43+AM44 -> 35064.6
A47: EBITDA (Earnings before Interest, Tax, Depreciation & Amortization) | D47: =D37-D45 -> -11508 | E47: =E37-E45 -> -24589.6 | F47: =F37-F45 -> -24589.6 | G47: =G37-G45 -> -24589.6 | H47: =H37-H45 -> -24589.6 | I47: =I37-I45 -> -24589.6 | J47: =J37-J45 -> -5849.6 | K47: =K37-K45 -> -24589.6 | ... AM47: =AM37-AM45 -> -16324.6
A48: EBITDA margin | D48: =IFERROR(D47/D25,0) -> 0 | E48: =IFERROR(E47/E25,0) -> 0 | F48: =IFERROR(F47/F25,0) -> 0 | G48: =IFERROR(G47/G25,0) -> 0 | H48: =IFERROR(H47/H25,0) -> 0 | I48: =IFERROR(I47/I25,0) -> 0 | J48: =IFERROR(J47/J25,0) -> -0.24373333 | K48: =IFERROR(K47/K25,0) -> 0 | ... AM48: =IFERROR(AM47/AM25,0) -> -0.68019167
A50: Financing & Investment
A51: Equity investment | D51: ='Inputs - Sales & Investment'!D29 -> 150000 | E51: ='Inputs - Sales & Investment'!E29 -> 0 | F51: ='Inputs - Sales & Investment'!F29 -> 0 | G51: ='Inputs - Sales & Investment'!G29 -> 0 | H51: ='Inputs - Sales & Investment'!H29 -> 0 | I51: ='Inputs - Sales & Investment'!I29 -> 0 | J51: ='Inputs - Sales & Investment'!J29 -> 0 | K51: ='Inputs - Sales & Investment'!K29 -> 0 | ... AM51: ='Inputs - Sales & Investment'!AM29 -> 0
A52: Debt | D52: ='Inputs - Sales & Investment'!D30 -> 0 | E52: ='Inputs - Sales & Investment'!E30 -> 0 | F52: ='Inputs - Sales & Investment'!F30 -> 0 | G52: ='Inputs - Sales & Investment'!G30 -> 0 | H52: ='Inputs - Sales & Investment'!H30 -> 0 | I52: ='Inputs - Sales & Investment'!I30 -> 0 | J52: ='Inputs - Sales & Investment'!J30 -> 0 | K52: ='Inputs - Sales & Investment'!K30 -> 0 | ... AM52: ='Inputs - Sales & Investment'!AM30 -> 0
A53: Pre-tax profit | D53: =D47+D56+D57-D59-D60 -> -11508 | E53: =E47+E56+E57-E59-E60 -> -24589.6 | F53: =F47+F56+F57-F59-F60 -> -24589.6 | G53: =G47+G56+G57-G59-G60 -> 25410.4 | H53: =H47+H56+H57-H59-H60 -> -24589.6 | I53: =I47+I56+I57-I59-I60 -> -24589.6 | J53: =J47+J56+J57-J59-J60 -> -5849.6 | K53: =K47+K56+K57-K59-K60 -> -24589.6 | ... AM53: =AM47+AM56+AM57-AM59-AM60 -> -16324.6
...

Sheet Forecast - P&L 
C1: FY 1 | D1: FY 2 | E1: FY 3 | F1: Total FY 1-3
A2: Sales (units)
A3: ='Forecast - Cashflow'!A9 -> Isotretinoin Monitoring App - Annual Provider Subscription | C3: =SUM('Forecast - Cashflow'!D9:O9) -> 3 | D3: =SUM('Forecast - Cashflow'!P9:AA9) -> 6 | E3: =SUM('Forecast - Cashflow'!AB9:AM9) -> 15 | F3: =SUM(C3:E3) -> 24
A4: ='Forecast - Cashflow'!A10 -> Product 2 | C4: =SUM('Forecast - Cashflow'!D10:O10) -> 0 | D4: =SUM('Forecast - Cashflow'!P10:AA10) -> 0 | E4: =SUM('Forecast - Cashflow'!AB10:AM10) -> 0 | F4: =SUM(C4:E4) -> 0
A5: ='Forecast - Cashflow'!A11 -> Product 3 | C5: =SUM('Forecast - Cashflow'!D11:O11) -> 0 | D5: =SUM('Forecast - Cashflow'!P11:AA11) -> 0 | E5: =SUM('Forecast - Cashflow'!AB11:AM11) -> 0 | F5: =SUM(C5:E5) -> 0
A6: ='Forecast - Cashflow'!A12 -> Product 4 | C6: =SUM('Forecast - Cashflow'!D12:O12) -> 0 | D6: =SUM('Forecast - Cashflow'!P12:AA12) -> 0 | E6: =SUM('Forecast - Cashflow'!AB12:AM12) -> 0 | F6: =SUM(C6:E6) -> 0
A7: ='Forecast - Cashflow'!A13 -> Product 5 | C7: =SUM('Forecast - Cashflow'!D13:O13) -> 0 | D7: =SUM('Forecast - Cashflow'!P13:AA13) -> 0 | E7: =SUM('Forecast - Cashflow'!AB13:AM13) -> 0 | F7: =SUM(C7:E7) -> 0
A8: ='Forecast - Cashflow'!A14 -> Product 6 | C8: =SUM('Forecast - Cashflow'!D14:O14) -> 0 | D8: =SUM('Forecast - Cashflow'!P14:AA14) -> 0 | E8: =SUM('Forecast - Cashflow'!AB14:AM14) -> 0 | F8: =SUM(C8:E8) -> 0
A9: TOTAL | C9: =SUM(C3:C8) -> 3 | D9: =SUM(D3:D8) -> 6 | E9: =SUM(E3:E8) -> 15 | F9: =SUM(F3:F8) -> 24
A11: Av. Unit price | C11: =IFERROR(C19/C9,0) -> 24000 | D11: =IFERROR(D19/D9,0) -> 24000 | E11: =IFERROR(E19/E9,0) -> 24000 | F11: =IFERROR(F19/F9,0) -> 24000
A12: Revenue
A13: ='Forecast - Cashflow'!A19 -> Isotretinoin Monitoring App - Annual Provider Subscription | C13: =SUM('Forecast - Cashflow'!D19:O19) -> 72000 | D13: =SUM('Forecast - Cashflow'!P19:AA19) -> 144000 | E13: =SUM('Forecast - Cashflow'!AB19:AM19) -> 360000 | F13: =SUM(C13:E13) -> 576000
A14: ='Forecast - Cashflow'!A20 -> Product 2 | C14: =SUM('Forecast - Cashflow'!D20:O20) -> 0 | D14: =SUM('Forecast - Cashflow'!P20:AA20) -> 0 | E14: =SUM('Forecast - Cashflow'!AB20:AM20) -> 0 | F14: =SUM(C14:E14) -> 0
A15: ='Forecast - Cashflow'!A21 -> Product 3 | C15: =SUM('Forecast - Cashflow'!D21:O21) -> 0 | D15: =SUM('Forecast - Cashflow'!P21:AA21) -> 0 | E15: =SUM('Forecast - Cashflow'!AB21:AM21) -> 0 | F15: =SUM(C15:E15) -> 0
A16: ='Forecast - Cashflow'!A22 -> Product 4 | C16: =SUM('Forecast - Cashflow'!D22:O22) -> 0 | D16: =SUM('Forecast - Cashflow'!P22:AA22) -> 0 | E16: =SUM('Forecast - Cashflow'!AB22:AM22) -> 0 | F16: =SUM(C16:E16) -> 0
A17: ='Forecast - Cashflow'!A23 -> Product 5 | C17: =SUM('Forecast - Cashflow'!D23:O23) -> 0 | D17: =SUM('Forecast - Cashflow'!P23:AA23) -> 0 | E17: =SUM('Forecast - Cashflow'!AB23:AM23) -> 0 | F17: =SUM(C17:E17) -> 0
A18: ='Forecast - Cashflow'!A24 -> Product 6 | C18: =SUM('Forecast - Cashflow'!D24:O24) -> 0 | D18: =SUM('Forecast - Cashflow'!P24:AA24) -> 0 | E18: =SUM('Forecast - Cashflow'!AB24:AM24) -> 0 | F18: =SUM(C18:E18) -> 0
A19: TOTAL INCOME | C19: =SUM(C13:C18) -> 72000 | D19: =SUM(D13:D18) -> 144000 | E19: =SUM(E13:E18) -> 360000 | F19: =SUM(F13:F18) -> 576000
A21: Less Cost of Sales
A22: ='Forecast - Cashflow'!A19 -> Isotretinoin Monitoring App - Annual Provider Subscription | C22: =SUM('Forecast - Cashflow'!D29:O29) -> 15780 | D22: =SUM('Forecast - Cashflow'!P29:AA29) -> 31560 | E22: =SUM('Forecast - Cashflow'!AB29:AM29) -> 78900 | F22: =SUM(C22:E22) -> 126240
A23: ='Forecast - Cashflow'!A20 -> Product 2 | C23: =SUM('Forecast - Cashflow'!D30:O30) -> 0 | D23: =SUM('Forecast - Cashflow'!P30:AA30) -> 0 | E23: =SUM('Forecast - Cashflow'!AB30:AM30) -> 0 | F23: =SUM(C23:E23) -> 0
A24: ='Forecast - Cashflow'!A21 -> Product 3 | C24: =SUM('Forecast - Cashflow'!D31:O31) -> 0 | D24: =SUM('Forecast - Cashflow'!P31:AA31) -> 0 | E24: =SUM('Forecast - Cashflow'!AB31:AM31) -> 0 | F24: =SUM(C24:E24) -> 0
A25: ='Forecast - Cashflow'!A22 -> Product 4 | C25: =SUM('Forecast - Cashflow'!D32:O32) -> 0 | D25: =SUM('Forecast - Cashflow'!P32:AA32) -> 0 | E25: =SUM('Forecast - Cashflow'!AB32:AM32) -> 0 | F25: =SUM(C25:E25) -> 0
A26: ='Forecast - Cashflow'!A23 -> Product 5 | C26: =SUM('Forecast - Cashflow'!D33:O33) -> 0 | D26: =SUM('Forecast - Cashflow'!P33:AA33) -> 0 | E26: =SUM('Forecast - Cashflow'!AB33:AM33) -> 0 | F26: =SUM(C26:E26) -> 0
A27: ='Forecast - Cashflow'!A24 -> Product 6 | C27: =SUM('Forecast - Cashflow'!D34:O34) -> 0 | D27: =SUM('Forecast - Cashflow'!P34:AA34) -> 0 | E27: =SUM('Forecast - Cashflow'!AB34:AM34) -> 0 | F27: =SUM(C27:E27) -> 0
A28: TOTAL COST OF SALES | C28: =SUM(C22:C27) -> 15780 | D28: =SUM(D22:D27) -> 31560 | E28: =SUM(E22:E27) -> 78900 | F28: =SUM(F22:F27) -> 126240
A30: GROSS PROFIT | C30: =C19-C28 -> 56220 | D30: =D19-D28 -> 112440 | E30: =E19-E28 -> 281100 | F30: =F19-F28 -> 449760
A31: Gross Margin % | C31: =IFERROR(C30/C19,0) -> 0.78083333 | D31: =IFERROR(D30/D19,0) -> 0.78083333 | E31: =IFERROR(E30/E19,0) -> 0.78083333 | F31: =IFERROR(F30/F19,0) -> 0.78083333
A33: Operating Expenses
A34: ='Inputs - Fixed Costs (OpEx)'!A7 -> General & Administrative Costs | C34: =SUM('Forecast - Cashflow'!D41:O41) -> 48696 | D34: =SUM('Forecast - Cashflow'!P41:AA41) -> 48024 | E34: =SUM('Forecast - Cashflow'!AB41:AM41) -> 77796 | F34: =SUM(C34:E34) -> 174516
A35: ='Inputs - Fixed Costs (OpEx)'!A27 -> Staff Costs | C35: =SUM('Forecast - Cashflow'!D42:O42) -> 143897.6 | D35: =SUM('Forecast - Cashflow'!P42:AA42) -> 156979.2 | E35: =SUM('Forecast - Cashflow'!AB42:AM42) -> 156979.2 | F35: =SUM(C35:E35) -> 457856
A36: ='Inputs - Fixed Costs (OpEx)'!A44 -> Marketing Expenses | C36: =SUM('Forecast - Cashflow'!D43:O43) -> 28200 | D36: =SUM('Forecast - Cashflow'!P43:AA43) -> 57600 | E36: =SUM('Forecast - Cashflow'!AB43:AM43) -> 108000 | F36: =SUM(C36:E36) -> 193800
A37: ='Inputs - Fixed Costs (OpEx)'!A59 -> Other Central Expenses | C37: =SUM('Forecast - Cashflow'!D44:O44) -> 61200 | D37: =SUM('Forecast - Cashflow'!P44:AA44) -> 57600 | E37: =SUM('Forecast - Cashflow'!AB44:AM44) -> 78000 | F37: =SUM(C37:E37) -> 196800
A38: TOTAL OPERATING EXPENSES | C38: =C36 -> 28200 | D38: =D36 -> 57600 | E38: =E36 -> 108000 | F38: =F36 -> 193800
A39: As % of Income | C39: =IFERROR(C38/C19,0) -> 0.39166667 | D39: =IFERROR(D38/D19,0) -> 0.4 | E39: =IFERROR(E38/E19,0) -> 0.3 | F39: =IFERROR(F38/F19,0) -> 0.33645833
A41: EBITDA | C41: =C30-C38 -> 28020 | D41: =D30-D38 -> 54840 | E41: =E30-E38 -> 173100 | F41: =F30-F38 -> 255960
A43: Non-operating Income
A44: Grant revenue | C44: =SUM('Forecast - Cashflow'!D56:O56) -> 50000 | D44: =SUM('Forecast - Cashflow'!P56:AA56) -> 0 | E44: =SUM('Forecast - Cashflow'!AB56:AM56) -> 0 | F44: =SUM(C44:E44) -> 50000
A45: Interest Income | C45: =SUM('Forecast - Cashflow'!D57:O57) -> 0 | D45: =SUM('Forecast - Cashflow'!P57:AA57) -> 0 | E45: =SUM('Forecast - Cashflow'!AB57:AM57) -> 0 | F45: =SUM(C45:E45) -> 0
A46: Non-operating Expenses
...
